# try-except
In Python, the `try-except` block is used for **exception handling**. It allows you to catch and handle errors gracefully without crashing the program. Here's a detailed explanation of how the `try-except` structure works, along with an example.

### Structure of Try-Except

1. **`try` Block**: You place the code that may raise an exception inside the `try` block. If an exception occurs during the execution of this code, Python will immediately stop executing the remaining code in the `try` block and jump to the corresponding `except` block.

2. **`except` Block**: The `except` block is where you define how to handle the exception. You can catch specific exceptions or use a generic `except` to catch any exception.

### Syntax

```python
try:
    # Code that may raise an exception
except ExceptionType:
    # Code to handle the exception
```

### Example of Try-Except

Hereâ€™s a simple example demonstrating how to use `try-except` to handle a potential error when converting user input into an integer:

```python
def get_integer_input():
    while True:
        user_input = input("Please enter an integer: ")
        try:
            # Try to convert the input to an integer
            number = int(user_input)
            return number  # Return the valid integer
        except ValueError:
            # Handle the case where conversion fails
            print("That's not a valid integer. Please try again.")

# Example usage
result = get_integer_input()
print(f"You entered: {result}")
```

### Explanation of the Example:

1. **Function Definition**: The function `get_integer_input()` prompts the user to enter an integer.

2. **Infinite Loop**: The `while True:` loop continues until a valid integer is entered.

3. **Try Block**: 
   - Inside the loop, the code tries to convert the user input to an integer using `int(user_input)`.
   - If the input is a valid integer, it returns the integer.

4. **Except Block**: 
   - If the input is not a valid integer (e.g., a string like "abc"), a `ValueError` is raised.
   - The corresponding `except ValueError:` block catches this exception and prints an error message, prompting the user to try again.

5. **Loop Continuation**: The loop will continue until a valid integer is entered. When a valid integer is provided, it breaks out of the loop, and the function returns the integer value.

### Summary

- The **`try-except`** structure is crucial for handling exceptions in Python.
- It allows you to write robust code that can handle errors without crashing.
- You can catch specific exceptions or use a generic `except` for broader error handling.
- This mechanism improves user experience by providing clear error messages and allowing for corrective actions.