# Ordering of Except Branches
In Python, when using multiple `except` blocks to handle exceptions, the order in which you place these `except` blocks matters. Python will check each `except` block in the order they are written and will execute the first one that matches the raised exception. This means that more specific exceptions should be placed before more general exceptions to ensure they are caught correctly.

### Ordering of Except Branches

1. **Specific Exceptions First**: Always list specific exceptions before general exceptions. For example, `ValueError` should be listed before `Exception`, as `Exception` will catch all exceptions, including `ValueError`.

2. **General Exception Last**: If you want to catch all types of exceptions, use a general exception at the end of your `except` blocks. This ensures that specific exceptions are handled appropriately before falling back to the general handler.

### Example of Ordering Except Branches

Hereâ€™s an example that demonstrates the proper ordering of `except` blocks:

```python
def divide_numbers(num1, num2):
    try:
        result = num1 / num2
        return f"The result is: {result}"
    except ZeroDivisionError:
        return "Error: Cannot divide by zero."
    except TypeError:
        return "Error: Please provide numbers only."
    except Exception as e:
        return f"An unexpected error occurred: {e}"

# Example usages
print(divide_numbers(10, 2))    # Output: The result is: 5.0
print(divide_numbers(10, 0))    # Output: Error: Cannot divide by zero.
print(divide_numbers(10, 'a'))  # Output: Error: Please provide numbers only.
print(divide_numbers('10', '2'))  # Output: Error: Please provide numbers only.
print(divide_numbers(10, None))  # Output: Error: Please provide numbers only.
```

### Explanation of the Example:

1. **Function Definition**: The function `divide_numbers(num1, num2)` attempts to divide two numbers.

2. **Try Block**: The division operation is placed inside the `try` block.

3. **Except Blocks**:
   - **`ZeroDivisionError`**: This specific exception is checked first. If `num2` is zero, it catches the division by zero error.
   - **`TypeError`**: This second `except` block catches errors related to invalid types (e.g., if a string is passed instead of a number).
   - **`Exception`**: The last `except` block catches any other unexpected exceptions. By using `as e`, it allows you to capture the exception instance and access the error message.

### Example of Incorrect Ordering

If the ordering were incorrect, such as placing the general `Exception` before the specific exceptions, it would lead to unintended behavior:

```python
def incorrect_divide_numbers(num1, num2):
    try:
        result = num1 / num2
        return f"The result is: {result}"
    except Exception as e:  # This will catch all exceptions, including ZeroDivisionError and TypeError
        return f"An unexpected error occurred: {e}"
    except ZeroDivisionError:
        return "Error: Cannot divide by zero."  # This will never be reached
    except TypeError:
        return "Error: Please provide numbers only."  # This will never be reached

# Example usages
print(incorrect_divide_numbers(10, 0))    # Output: An unexpected error occurred: division by zero
print(incorrect_divide_numbers(10, 'a'))  # Output: An unexpected error occurred: unsupported operand type(s) for /: 'int' and 'str'
```

### Summary

- **Ordering matters** in `except` blocks: always place more specific exceptions before more general ones.
- This ensures that specific error handling occurs first, allowing you to provide tailored responses for different types of errors.
- If a general `except` block is placed first, it can prevent more specific exceptions from being caught, leading to less informative error messages or unintended behavior.