# propagating exceptions
In Python, **propagating exceptions** refers to the process of allowing an exception to continue up the call stack instead of handling it in the current block of code. When an exception is raised in a function and not caught there, it can propagate to the calling function, potentially leading to error handling at a higher level.

### How Propagation Works

1. **Raising an Exception**: When an exception occurs, Python looks for an `except` block in the current function. If it finds one that matches the exception, it handles it. If not, the exception propagates to the caller.
2. **Call Stack**: The call stack is a stack data structure that stores information about the active subroutines (functions) of a computer program. When an exception is propagated, Python moves up the stack until it finds a matching `except` block or until the program terminates if no handler is found.

### Example of Exception Propagation

Hereâ€™s a simple example demonstrating how exceptions can propagate through multiple layers of function calls:

```python
def divide(a, b):
    try:
        return a / b  # This might raise a ZeroDivisionError
    except ZeroDivisionError:
        print("Error: Division by zero occurred.")
        raise  # Re-raise the exception to propagate it

def calculate():
    return divide(10, 0)  # Call the divide function with zero

try:
    result = calculate()  # Call the calculate function
except ZeroDivisionError:
    print("Caught a ZeroDivisionError in the main block.")

print("Program continues...")
```

### Explanation of the Example:

1. **Function `divide(a, b)`**:
   - This function attempts to divide `a` by `b`. If `b` is zero, a `ZeroDivisionError` is raised.
   - The `except` block catches the exception and prints an error message. It then uses `raise` to propagate the exception back to the caller.

2. **Function `calculate()`**:
   - This function calls `divide(10, 0)`, which will raise a `ZeroDivisionError`.

3. **Main Block**:
   - The `calculate()` function is called inside a `try` block.
   - When `calculate()` calls `divide()`, the division by zero occurs, and the exception is caught in `divide()`.
   - After printing the error message, the `raise` statement re-raises the `ZeroDivisionError`, which propagates up to the `try` block in the main code.
   - The main block has its own `except` block for handling `ZeroDivisionError`, which catches the propagated exception and prints another error message.

### Output

When the above code is run, it will produce the following output:

```
Error: Division by zero occurred.
Caught a ZeroDivisionError in the main block.
Program continues...
```

### Summary

- **Exception propagation** allows exceptions to move up the call stack when they are not handled in the current function.
- You can use `raise` to re-raise an exception after handling it, allowing higher-level functions to manage the error.
- This mechanism helps create a more organized and modular error-handling strategy, as different layers of your program can decide how to handle specific exceptions.